Workbook
Name dualWielder: v2.1!$AZ$44
Name thrown: v2.1!$AX$44
Name thrownText: v2.1!$AX$43
Name intMod: v2.1!$C$28
Name ClericLevel: 'Class Info'!$AP$24
Name greatWeaponFighting: v2.1!$AT$44
Name race: v2.1!$AQ$5
Name name: v2.1!$C$6
Name racialSpeed: v2.1!$AT$5
Name unarmedFighting: v2.1!$AY$44
Name FighterLevel: 'Class Info'!$AP$43
Name chaMod: v2.1!$C$38
Name unarmedText: v2.1!$AY$43
Name MonkLevel: 'Class Info'!$AP$52
Name twoWeaponFighting: v2.1!$AU$44
Name twfText: v2.1!$AU$43
Name invocations: v2.1!$AQ$61
Name spellAttackBonus: v2.1!$AI$91
Name WarlockLevel: 'Class Info'!$AP$88
Name closeQuarters: v2.1!$AW$44
Name castingClass: v2.1!$C$91
Name weaponProficiencies: v2.1!$I$50
Name armorProficiencies: v2.1!$AQ$65
Name dexMod: v2.1!$C$18
Name naturalArmorAC: v2.1!$AS$26
Name mariner: v2.1!$AV$44
Name armor: v2.1!$AQ$24
Name classAndLevel: v2.1!$T$5
Name strMod: v2.1!$C$13
Name proficiencyBonus: v2.1!$H$14
Name PaladinLevel: 'Class Info'!$AP$60
Name casterLevel: v2.1!$AT$16
Name WizardLevel: 'Class Info'!$AP$95
Name defense: v2.1!$AR$44
Name duelingText: v2.1!$AS$43
Name SorcererLevel: 'Class Info'!$AP$82
Name armoredAC: v2.1!$AQ$26
Name shield: v2.1!$AQ$25
Name speedBonus: v2.1!$AQ$18
Name dueling: v2.1!$AS$44
Name RogueLevel: 'Class Info'!$AP$74
Name DruidLevel: 'Class Info'!$AP$37
Name RangerLevel: 'Class Info'!$AP$68
Name closeQuartersText: v2.1!$AW$43
Name archeryText: v2.1!$AQ$43
Name averageHitPoints: v2.1!$AU$16
Name unarmoredAC: v2.1!$AR$26
Name gwfText: v2.1!$AT$43
Name jackOfAllTrades: v2.1!$AQ$59
Name archery: v2.1!$AQ$44
Name BardLevel: 'Class Info'!$AP$18
Name feats: v2.1!$AQ$60
Name level: v2.1!$AL$6
Name BarbarianLevel: 'Class Info'!$AP$11
Name monkMagic: 'Attack Info'!$AP$1
Name castingAbility: v2.1!$U$91
Name altClassBasedAC: v2.1!$AT$26
Name wisMod: v2.1!$C$33
Name fightingStyles: v2.1!$AQ$62
Name raceResists: v2.1!$AV$5

Sheet v2.1
A2: =if(C174="",if(isnumber(find("Zim",C6)),image("https://i.imgur.com/T5OD9a5.png",2),if(and(AV16<>"",countif(AQ155:AQ180,AV16)),image(vlookup(AV16,AQ155:AS180,2,false),2),image("http://i.imgur.com/3GVZzam.png",2))),image(vlookup(C174,AQ155:AS180,2,false),2)) | T2: =if(and(name="",classAndLevel="",race="",level="",C16=0,C21=0,C26=0,C31=0,C36=0,C41=0),"Click [File] then [Make a copy...] to use the sheet for yourself.",if(and(sum(AT6:AT15)<>level,classAndLevel<>""),"Total class levels must equal character level","")) | AQ2: Hide these columns. There should be no need to alter them (mostly). Customization and homebrew are mostly handled by the Info pages.
S3: =if(C174="Magic",IMAGE("http://i.imgur.com/2jwsXWa.png",2),"") | T3: =if(and(name="",classAndLevel="",race="",level="",C16=0,C21=0,C26=0,C31=0,C36=0,C41=0),"Check [?] for help. And read all the notes!",if(and(sum(AT6:AT15)<>level,classAndLevel<>""),"If you are using a homebrew class, enter its details on the Class Info page.",""))
S4: =IMAGE("https://i.imgur.com/OlUFGxq.png",2) | AO4: =IMAGE("http://i.imgur.com/nWCUyCa.png",2) | AQ4: 2.1
AE5: Thalysson | AK5: =if(AL6<5,IMAGE("http://i.imgur.com/zDHOU0r.png",2),if(AL6<11,IMAGE("http://i.imgur.com/0jIT5AA.png",2),if(AL6<17,IMAGE("http://i.imgur.com/qN7jDhM.png",2),IMAGE("http://i.imgur.com/brqhftZ.png",2)))) | AL5: LEVEL | AN5: =if(AL6<5,IMAGE("http://i.imgur.com/stPe4fo.png",2),if(AL6<11,IMAGE("http://i.imgur.com/PVGeU3d.png",2),if(AL6<17,IMAGE("http://i.imgur.com/mnwcuFl.png",2),IMAGE("http://i.imgur.com/TfiOReG.png",2)))) | AQ5: =IFERROR(__xludf.DUMMYFUNCTION("iferror(array_constrain(split(textjoin(""~"",True,filter('Race Info'!$B$7:$AN180,'Race Info'!$B$7:$B180<>"""",lower('Race Info'!$B$7:$B180=$T$7))),""~""),1,11),"""")"),"Human") -> Human | AR5: =IFERROR(__xludf.DUMMYFUNCTION("""COMPUTED_VALUE"""),"str +1, dex +1, con +1, int +1, wis +1, cha +1") -> str +1, dex +1, con +1, int +1, wis +1, cha +1 | AS5: =IFERROR(__xludf.DUMMYFUNCTION("""COMPUTED_VALUE"""),"-") -> - | AT5: =IFERROR(__xludf.DUMMYFUNCTION("""COMPUTED_VALUE"""),30.0) -> 30 | AU5: =IFERROR(__xludf.DUMMYFUNCTION("""COMPUTED_VALUE"""),"-") -> - | AV5: =IFERROR(__xludf.DUMMYFUNCTION("""COMPUTED_VALUE"""),"-") -> - | AW5: =IFERROR(__xludf.DUMMYFUNCTION("""COMPUTED_VALUE"""),"Common, 1 extra") -> Common, 1 extra | AX5: =IFERROR(__xludf.DUMMYFUNCTION("""COMPUTED_VALUE"""),"-") -> - | AY5: =IFERROR(__xludf.DUMMYFUNCTION("""COMPUTED_VALUE"""),"-") -> - | AZ5: =IFERROR(__xludf.DUMMYFUNCTION("""COMPUTED_VALUE"""),"-") -> - | BC5: =IFERROR(__xludf.DUMMYFUNCTION("if($T$5<>"""",array_constrain(iferror(filter(BA6:BA15,BA6:BA15<>"""",isnumber(find(""10"",BA6:BA15))),""10+dex""),1,1),"""")"),"")
T6: CLASS(ES) & LEVEL(S) | AE6: PLAYER NAME | AL6: =if(AE7<>"",if(AE7<300,1,if(AE7<900,2,if(AE7<2700,3,if(AE7<6500,4,if(AE7<14000,5,if(AE7<23000,6,if(AE7<34000,7,if(AE7<48000,8,if(AE7<64000,9,if(AE7<85000,10,if(AE7<100000,11,if(AE7<120000,12,if(AE7<140000,13,if(AE7<165000,14,if(AE7<195000,15,if(AE7<225000,16,if(AE7<265000,17,if(AE7<305000,18,if(AE7<355000,19,20))))))))))))))))))),"") | AQ6: {=iferror(vlookup(AR6:AR15,'Class Info'!B7:K180,10,false),"")} | AR6: =IFERROR(__xludf.DUMMYFUNCTION("iferror(transpose(unique(filter(split(proper($T$5),"" ""),iserror(find(split(proper($T$5),"" "")&"" 0"",proper($T$5))),isnumber(find(proper(split($T$5,"" ""))&""-"",proper(textjoin(""-"",True,'Class Info'!$B$7:$B180,""-""))))))),"""")"),"") | AS6: =IFERROR(__xludf.DUMMYFUNCTION("if($AR6<>"""",iferror(array_constrain(filter('Class Info'!$E$7:$E180,'Class Info'!$B$7:$B180=$AR6,'Class Info'!$E$7:$E180<>"""",isnumber(find(proper('Class Info'!$E$7:$E180),proper($T$5)))),1,1),""-""),"""")"),"") | AT6: =IFERROR(__xludf.DUMMYFUNCTION("if(and(AR6<>"""",isnumber(find(lower(AR6),lower($T$5)))),int(substitute(if(regexmatch(proper($T$5),proper(AR6)&"" [0-9]+""),regexextract(proper($T$5),proper(AR6)&"" [0-9]+""),level),proper(AR6)&"" "","""")),"""")"),"") | AU6: =IFERROR(__xludf.DUMMYFUNCTION("arrayformula(if(AT6:AT15,AT6:AT15*(int(regexextract(AQ6:AQ15,""[0-9]+""))/2+1 +if(vlookup(AR6:AR15,'Class Info'!B7:O180,14,false)<>""-"",vlookup(AR6:AR15,'Class Info'!B7:O180,14,false),0) +if(vlookup(AS6:AS15,'Class Info'!E7:O180,11,false)<>""-"",vlookup("&"AS6:AS15,'Class Info'!E7:O180,11,false),0)) +if(AV6:AV15<>"""",(int(regexextract(AQ6:AQ15,""[0-9]+""))/2-1),0),""""))"),"") | AV6: =if(AR6<>"", vlookup(AR6,'Class Info'!B7:Q180,16,false) &if(vlookup(AR6,'Class Info'!B7:X180,23,false)<>"-",", "&vlookup(AR6,'Class Info'!B7:X180,23,false),""), "" ) | AW6: {=iferror(vlookup(AR6:AR15,'Class Info'!B7:AB180,27,false) &if(vlookup(AS6:AS15,'Class Info'!E7:AB180,24,false)<>"-",if(AS6:AS15<>"-",", "&vlookup(AS6:AS15,'Class Info'!E7:AB180,24,false),""),""),"")} | AX6: {=iferror(if(vlookup(AR6:AR15,'Class Info'!B7:AG180,32,false)<>"-",vlookup(AR6:AR15,'Class Info'!B7:AG180,32,false),"") &if(vlookup(AS6:AS15,'Class Info'!E7:AG180,29,false)<>"-",if(AS6:AS15<>"-",vlookup(AS6:AS15,'Class Info'!E7:AG180,29,false),""),""),"")} | AY6: {=iferror(if(vlookup(AR6:AR15,'Class Info'!B7:AJ180,35,false)<>"-",vlookup(AR6:AR15,'Class Info'!B7:AJ180,35,false),"") &if(AS6:AS15<>"-",if(vlookup(AS6:AS15,'Class Info'!E7:AJ180,32,false)<>"-",vlookup(AS6:AS15,'Class Info'!E7:AJ180,32,false),""),""),"")} | AZ6: {=if(AR6:AR15<>"",int(iferror(if(vlookup(AR6:AR15,'Class Info'!B7:AM180,38,false)<>"-",vlookup(AR6:AR15,'Class Info'!B7:AM180,38,false),"") &if(vlookup(AS6:AS15,'Class Info'!E7:AM180,35,false)<>"-",vlookup(AS6:AS15,'Class Info'!E7:AM180,35,false),""),"")),"")} | BA6: {=iferror(if(vlookup(AR6:AR15,'Class Info'!B7:I180,8,false)<>"-",if(vlookup(AR6:AR15,'Class Info'!B7:I180,8,false)<>"10+dex",vlookup(AR6:AR15,'Class Info'!B7:I180,8,false),""),"") &if(AS6:AS15<>"-",if(vlookup(AS6:AS15,'Class Info'!E7:I180,5,false)<>"-",vlookup(AS6:AS15,'Class Info'!E7:I180,5,false),""),""),"")} | BB6: {=if(AR6:AR15<>"",if(vlookup(AR6:AR15,'Class Info'!B7:M180,12,false)<>"-",vlookup(AR6:AR15,'Class Info'!B7:M180,12,false),"") &if(vlookup(AS6:AS15,'Class Info'!E7:M180,9,false)<>"-",vlookup(AS6:AS15,'Class Info'!E7:M180,9,false),""),"")}
T7: Human | AH7: =if(AE7<>"",choose(AL6,300,900,2700,6500,14000,23000,34000,48000,64000,85000,100000,120000,140000,165000,195000,225000,265000,305000,355000,0),"") | AS7: =IFERROR(__xludf.DUMMYFUNCTION("if($AR7<>"""",iferror(array_constrain(filter('Class Info'!$E$7:$E180,'Class Info'!$B$7:$B180=$AR7,'Class Info'!$E$7:$E180<>"""",isnumber(find(proper('Class Info'!$E$7:$E180),proper($T$5)))),1,1),""-""),"""")"),"") | AT7: =IFERROR(__xludf.DUMMYFUNCTION("if(and(AR7<>"""",isnumber(find(lower(AR7),lower($T$5)))),int(substitute(if(regexmatch(proper($T$5),proper(AR7)&"" [0-9]+""),regexextract(proper($T$5),proper(AR7)&"" [0-9]+""),level),proper(AR7)&"" "","""")),"""")"),"") | AU7: =IFERROR(__xludf.DUMMYFUNCTION("""COMPUTED_VALUE"""),"")
A8: =if(C174="",if(isnumber(find("Zim",C6)),image("https://i.imgur.com/G8kk6zf.png",2),if( and(AV16<>"",countif(AQ155:AQ180,AV16)),image("https://i.imgur.com/G8kk6zf.png",2),image("http://i.imgur.com/miU7se3.png",2))),image(vlookup(C174,AQ155:AS180,3,false),2)) | T8: =if(and(T7<>"",AQ5=""),"To use a custom race, add it on the 'Race Info' tab.","RACE") -> RACE | AE8: EXPERIENCE | AH8: NEXT LEVEL | AS8: =IFERROR(__xludf.DUMMYFUNCTION("if($AR8<>"""",iferror(array_constrain(filter('Class Info'!$E$7:$E180,'Class Info'!$B$7:$B180=$AR8,'Class Info'!$E$7:$E180<>"""",isnumber(find(proper('Class Info'!$E$7:$E180),proper($T$5)))),1,1),""-""),"""")"),"") | AT8: =IFERROR(__xludf.DUMMYFUNCTION("if(and(AR8<>"""",isnumber(find(lower(AR8),lower($T$5)))),int(substitute(if(regexmatch(proper($T$5),proper(AR8)&"" [0-9]+""),regexextract(proper($T$5),proper(AR8)&"" [0-9]+""),level),proper(AR8)&"" "","""")),"""")"),"") | AU8: =IFERROR(__xludf.DUMMYFUNCTION("""COMPUTED_VALUE"""),"")
S9: =IMAGE("https://i.imgur.com/6avJSbK.png",2) | AS9: =IFERROR(__xludf.DUMMYFUNCTION("if($AR9<>"""",iferror(array_constrain(filter('Class Info'!$E$7:$E180,'Class Info'!$B$7:$B180=$AR9,'Class Info'!$E$7:$E180<>"""",isnumber(find(proper('Class Info'!$E$7:$E180),proper($T$5)))),1,1),""-""),"""")"),"") | AT9: =IFERROR(__xludf.DUMMYFUNCTION("if(and(AR9<>"""",isnumber(find(lower(AR9),lower($T$5)))),int(substitute(if(regexmatch(proper($T$5),proper(AR9)&"" [0-9]+""),regexextract(proper($T$5),proper(AR9)&"" [0-9]+""),level),proper(AR9)&"" "","""")),"""")"),"") | AU9: =IFERROR(__xludf.DUMMYFUNCTION("""COMPUTED_VALUE"""),"")
B10: =IMAGE("https://i.imgur.com/u3YeDks.png",2) | G10: =IMAGE("https://i.imgur.com/0VlrXCA.png",4, 734, 20) | O10: =IMAGE("https://i.imgur.com/GFrq6pf.png",4, 797, 20) | Q10: =IMAGE("https://i.imgur.com/sMN3tei.png",2) | AC10: HP | AD10: =IMAGE("https://i.imgur.com/sMN3tei.png",2) | AS10: =IFERROR(__xludf.DUMMYFUNCTION("if($AR10<>"""",iferror(array_constrain(filter('Class Info'!$E$7:$E180,'Class Info'!$B$7:$B180=$AR10,'Class Info'!$E$7:$E180<>"""",isnumber(find(proper('Class Info'!$E$7:$E180),proper($T$5)))),1,1),""-""),"""")"),"") | AT10: =IFERROR(__xludf.DUMMYFUNCTION("if(and(AR10<>"""",isnumber(find(lower(AR10),lower($T$5)))),int(substitute(if(regexmatch(proper($T$5),proper(AR10)&"" [0-9]+""),regexextract(proper($T$5),proper(AR10)&"" [0-9]+""),level),proper(AR10)&"" "","""")),"""")"),"") | AU10: =IFERROR(__xludf.DUMMYFUNCTION("""COMPUTED_VALUE"""),"")
B11: =IMAGE("https://i.imgur.com/VUGDDJt.png",4, 650, 20) | E11: =IMAGE("https://i.imgur.com/u9a6TBA.png",4, 650, 20) | H11: 0 | J11: =image("https://i.imgur.com/kI66z3t.png",2) | K11: INSPIRATION | Q11: =IMAGE("https://i.imgur.com/r6YjQVe.png",4, 377, 20) | T11: =IMAGE("https://i.imgur.com/k6zj6md.png",2) | U11: =IMAGE("http://i.imgur.com/C5Lv5CM.png",2) | V11: =IFERROR(__xludf.DUMMYFUNCTION("if(V15<>"""",V15, if(regexmatch(substitute(substitute(Additional!AR79,""("",""""),"")"",""""),""advantage on[a-z. ]+?initiative""), if(regexmatch(substitute(substitute(Additional!AR79,""("",""""),"")"",""""),""sadvantage on[.a-z ]+?initiative""), ""dis"&""",""adv""),if(countif(BC6:BC15,""adv"")>0,""adv"","""")))")," ") | X11: =IMAGE("https://i.imgur.com/k6zj6md.png",2) | Y11: =IMAGE("http://i.imgur.com/C5Lv5CM.png",2) | AB11: =IMAGE("http://i.imgur.com/pJkkaty.png",4, 377, 20) | AD11: =IMAGE("http://i.imgur.com/yqyqC2t.png",4, 377, 20) | AE11: BACKGROUND: | AO11: =IMAGE("http://i.imgur.com/40rhpIU.png",4, 377, 20) | AS11: =IFERROR(__xludf.DUMMYFUNCTION("if($AR11<>"""",iferror(array_constrain(filter('Class Info'!$E$7:$E180,'Class Info'!$B$7:$B180=$AR11,'Class Info'!$E$7:$E180<>"""",isnumber(find(proper('Class Info'!$E$7:$E180),proper($T$5)))),1,1),""-""),"""")"),"") | AT11: =IFERROR(__xludf.DUMMYFUNCTION("if(and(AR11<>"""",isnumber(find(lower(AR11),lower($T$5)))),int(substitute(if(regexmatch(proper($T$5),proper(AR11)&"" [0-9]+""),regexextract(proper($T$5),proper(AR11)&"" [0-9]+""),level),proper(AR11)&"" "","""")),"""")"),"") | AU11: =IFERROR(__xludf.DUMMYFUNCTION("""COMPUTED_VALUE"""),"")
C12: STR | R12: =if( or(dexMod="-",level=""), "-", max(armoredAC,unarmoredAC,naturalArmorAC,altClassBasedAC) +dualWielder ) -> - | V12: =IFERROR(__xludf.DUMMYFUNCTION("if(or(dexMod=""-"",level=""""), ""-"", dexMod +sum(filter(AY45:AY56,AY45:AY56<>""-"")) +max(jackOfAllTrades,iferror(if(and(vlookup(""Fighter"",$AR$6:$AS$15,2,false)=""Champion"",FighterLevel>=7),ceiling(proficiencyBonus/2),0),0)) +if(i"&"snumber(find(""alert"",feats)),5,0) +iferror(sum(arrayformula(int(filter(BB6:BB15,regexmatch(BB6:BB15,""[0-9]+""))))),0) +sum(arrayformula(int(iferror(substitute(regexextract(lower(filter({BA32:BA56;Additional!$BA$3:$BA$24},regexmatch(lower({BA32:"&"BA56;Additional!$BA$3:$BA$24}),""[0-9]+ bonus [a-z. ]+initiative""))),""[0-9]+ bonus to ""),"" bonus to "",""""),0)))) )"),"-") -> - | Z12: =IFERROR(__xludf.DUMMYFUNCTION("if(AQ5="""",""-"",iferror(int(regexextract(text(racialSpeed,0),""[0-9]+"")),30)+speedBonus)"),30.0) -> 30 | AS12: =IFERROR(__xludf.DUMMYFUNCTION("if($AR12<>"""",iferror(array_constrain(filter('Class Info'!$E$7:$E180,'Class Info'!$B$7:$B180=$AR12,'Class Info'!$E$7:$E180<>"""",isnumber(find(proper('Class Info'!$E$7:$E180),proper($T$5)))),1,1),""-""),"""")"),"") | AT12: =IFERROR(__xludf.DUMMYFUNCTION("if(and(AR12<>"""",isnumber(find(lower(AR12),lower($T$5)))),int(substitute(if(regexmatch(proper($T$5),proper(AR12)&"" [0-9]+""),regexextract(proper($T$5),proper(AR12)&"" [0-9]+""),level),proper(AR12)&"" "","""")),"""")"),"") | AU12: =IFERROR(__xludf.DUMMYFUNCTION("""COMPUTED_VALUE"""),"")
C13: =if(C15="-","-",INT((C15-10)/2)) -> - | AS13: =IFERROR(__xludf.DUMMYFUNCTION("if($AR13<>"""",iferror(array_constrain(filter('Class Info'!$E$7:$E180,'Class Info'!$B$7:$B180=$AR13,'Class Info'!$E$7:$E180<>"""",isnumber(find(proper('Class Info'!$E$7:$E180),proper($T$5)))),1,1),""-""),"""")"),"") | AT13: =IFERROR(__xludf.DUMMYFUNCTION("if(and(AR13<>"""",isnumber(find(lower(AR13),lower($T$5)))),int(substitute(if(regexmatch(proper($T$5),proper(AR13)&"" [0-9]+""),regexextract(proper($T$5),proper(AR13)&"" [0-9]+""),level),proper(AR13)&"" "","""")),"""")"),"") | AU13: =IFERROR(__xludf.DUMMYFUNCTION("""COMPUTED_VALUE"""),"")
H14: =IFERROR(__xludf.DUMMYFUNCTION("if(level="""","""",floor((level+7)/4)+iferror(sum(split(textjoin(""-"",True,AX45:AX49,AX50:AX56),""-"")),0))"),"") | J14: =image("https://i.imgur.com/v92a6gB.png",2) | K14: PROFICIENCY BONUS | R14: AC | V14: INIT | Z14: SPEED | AS14: =IFERROR(__xludf.DUMMYFUNCTION("if($AR14<>"""",iferror(array_constrain(filter('Class Info'!$E$7:$E180,'Class Info'!$B$7:$B180=$AR14,'Class Info'!$E$7:$E180<>"""",isnumber(find(proper('Class Info'!$E$7:$E180),proper($T$5)))),1,1),""-""),"""")"),"") | AT14: =IFERROR(__xludf.DUMMYFUNCTION("if(and(AR14<>"""",isnumber(find(lower(AR14),lower($T$5)))),int(substitute(if(regexmatch(proper($T$5),proper(AR14)&"" [0-9]+""),regexextract(proper($T$5),proper(AR14)&"" [0-9]+""),level),proper(AR14)&"" "","""")),"""")"),"") | AU14: =IFERROR(__xludf.DUMMYFUNCTION("""COMPUTED_VALUE"""),"")
C15: =IFERROR(__xludf.DUMMYFUNCTION("if(C16,min(30,max( iferror(int(trim(right(regexextract(Additional!$AR$79,lower(C12)&""[a-z]+? score is [0-9]+""),2))),0), iferror(int(trim(right(regexextract(Additional!$AR$79,lower(C12)&""[a-z]+? score changes to [0-9]+""),2))),0), min(iferror(int(trim(r"&"ight(regexextract(Additional!$AR$79,lower(C12)&""[a-z]+? [a-z ]+maximum of [0-9]+?""),2))),20+if(BarbarianLevel=20,4,0)), C16+if(BarbarianLevel=20,4,0)+ iferror(if(find(regexextract($AR$5,lower(C12)&"" \+[0-9]""),$AR$5)<iferror(find(""choose"",lower($AR$5"&")),len($AR$5)),int(right(regexextract($AR$5,lower(C12)&"" \+[0-9]""),1)),0),0)- iferror(if(find(regexextract($AR$5,lower(C12)&"" \-[0-9]""),$AR$5)<iferror(find(""choose"",lower($AR$5)),len($AR$5)),int(right(regexextract($AR$5,lower(C12)&"" \-[0-9]""),1)),"&"0),0) +D16)) +sum(arrayformula(int(iferror(trim(right(regexextract(lower(filter({BA$32:BA$56;Additional!$BA$3:$BA$24},regexmatch(lower({BA$32:BA$56;Additional!$BA$3:$BA$24}),lower(C12)&""[a-z]+? score increases by [0-9]+""))),lower(C12)&""[a-z]+? score in"&"creases by [0-9]+""),2)),0))))),""-"")"),"-") -> - | AE15: PERSONALITY TRAITS | AS15: =IFERROR(__xludf.DUMMYFUNCTION("if($AR15<>"""",iferror(array_constrain(filter('Class Info'!$E$7:$E180,'Class Info'!$B$7:$B180=$AR15,'Class Info'!$E$7:$E180<>"""",isnumber(find(proper('Class Info'!$E$7:$E180),proper($T$5)))),1,1),""-""),"""")"),"") | AT15: =IFERROR(__xludf.DUMMYFUNCTION("if(and(AR15<>"""",isnumber(find(lower(AR15),lower($T$5)))),int(substitute(if(regexmatch(proper($T$5),proper(AR15)&"" [0-9]+""),regexextract(proper($T$5),proper(AR15)&"" [0-9]+""),level),proper(AR15)&"" "","""")),"""")"),"") | AU15: =IFERROR(__xludf.DUMMYFUNCTION("""COMPUTED_VALUE"""),"")
C16: 0 | F16: =IFERROR(__xludf.DUMMYFUNCTION("arrayformula(if(P16:P23<>"""",P16:P23, if($AC$57<>""EQUIPPED ITEMS"",if(J16:J23<>"""",if(isnumber(find(J16:J23,""StrengthDexterity"")),""dis"", if(regexmatch(Additional!$AR$79,""advantage on all[a-z ]+?""&lower(J16:J23)&""[a-z ]+? sav saving throws""), "&" if(regexmatch(Additional!$AR$79,""sadvantage on all[a-z ]+""&lower(J16:J23)&""[a-z ]+? saving throws""), ""dis"",""adv""), if(regexmatch(substitute(lower($BA$5),"","",""""),""advantage on all[a-z ]+?""&lower(J16:J23)&""[a-z ]+?saving throws""), if(reg"&"exmatch(substitute(lower($BA$5),"","",""""),""sadvantage on all[a-z ]+?""&lower(J16:J23)&""[a-z ]+?saving throws""), ""dis"",""adv""),""""))),""""))))"),FALSE) -> FALSE | K16: =if(sum(H17:H23)=0,"Saving throws auto-populate.","") -> Saving throws auto-populate. | R16: Hit Point Max | U16: =if(and(level<>"",conMod<>"-"),level*C23+if(sum(rolledHitPoints)>0,sum(rolledHitPoints),averageHitPoints) +if(ISNUMBER(AU5),max(0,floor(AU5*level,1)),0) +if(isnumber(find("tough",feats)),level*2,0),"-") -> - | AQ16: =if(level<>"",iferror(vlookup(AJ11,AX69:AY180,2,false),""),"") | AR16: =IFERROR(__xludf.DUMMYFUNCTION("textjoin("", "",True,iferror(filter(J25:J42,isnumber(find(lower(J25:J42),mid(lower($AZ$5),iferror(find(""proficien"",$AZ$5),1),len($AZ$5))))),""""))"),"") | AS16: =if(level<>"",sum(AS17:AS20),"") | AT16: =IFERROR(__xludf.DUMMYFUNCTION("if(AR6<>"""",if( and(iferror(filter(v2.1!AX6:AX15,v2.1!AT6:AT15=index(AL6))=""Half Caster""),AL6=1),0, if( countif(AX6:AX15,""Half Caster"")+countif(AX6:AX15,""Artificer Casting"")+countif(AX6:AX15,""Full Caster"")+countif(AX6:AX15,"&"""Third Caster"")<2, sum(iferror(filter(v2.1!AT6:AT15,v2.1!AX6:AX15=""Full Caster""),0)) +ceiling(if(sum(iferror(filter(v2.1!AT6:AT15,v2.1!AX6:AX15=""Half Caster""),0))>1,sum(iferror(filter(v2.1!AT6:AT15,v2.1!AX6:AX15=""Half Caster"""&"),0)),0)/2) +ceiling(sum(iferror(filter(v2.1!AT6:AT15,v2.1!AX6:AX15=""Artificer Casting""),0))/2) +ceiling(if(sum(iferror(filter(v2.1!AT6:AT15,v2.1!AX6:AX15=""Third Caster""),0))>2,sum(iferror(filter(v2.1!AT6:AT15,v2.1!AX6:AX15=""Thi"&"rd Caster""),0)),0)/3), sum(iferror(filter(v2.1!AT6:AT15,v2.1!AX6:AX15=""Full Caster""),0)) +floor(sum(iferror(filter(v2.1!AT6:AT15,v2.1!AX6:AX15=""Half Caster""),0))/2) +ceiling(sum(iferror(filter(v2.1!AT6:AT15,v2.1!AX6:A"&"X15=""Artificer Casting""),0))/2) +floor(sum(iferror(filter(v2.1!AT6:AT15,v2.1!AX6:AX15=""Third Caster""),0))/3) ) ),"""")"),"") | AU16: =if(AR6<>"",sum(AU6:AU15),"") | AV16: =AR6 | AW16: =textjoin(", ",true,AV6:AW15,AY5) -> - | BA16: =IFERROR(__xludf.DUMMYFUNCTION("if($T$5<>"""",array_constrain(iferror(filter(BA6:BA15,BA6:BA15<>"""",iserror(find(""10"",BA6:BA15))),""10+dex""),1,1),"""")"),"")
C17: DEX | F17: =IFERROR(__xludf.DUMMYFUNCTION("""COMPUTED_VALUE"""),FALSE) -> FALSE | H17: =IFERROR(__xludf.DUMMYFUNCTION("if(or(regexmatch($AQ$63,lower(J17)),regexmatch($AW$16,J17)),1,0)"),0.0) -> 0 | I17: =IFERROR(__xludf.DUMMYFUNCTION("if(and(proficiencyBonus,indirect(left(lower($J17),3)&""Mod"")<>""-""), if($H17<>0,proficiencyBonus,0) +indirect(left(lower($J17),3)&""Mod"") +$AS$58 +sum(arrayformula(int(iferror(substitute(regexextract(lower(filter({BA$32:BA$56;Additional"&"!$BA$3:$BA$24},regexmatch(lower({BA$32:BA$56;Additional!$BA$3:$BA$24}),""[0-9]+ bonus to ""&lower($J17)&"" sav""))),""[0-9]+ bonus to ""&lower($J17)&"" sav""),"" bonus to ""&lower($J17)&"" sav"",""""),0)))),""-"")"),"-") -> - | J17: Strength | AQ17: =if(level<>"",if($AJ$11<>"",2,0)+$AS$16-countif($H$25:$H$42,"<>0"),"") | AR17: =IFERROR(__xludf.DUMMYFUNCTION("iferror(regexextract(textjoin("", "",True,filter($J$25:$J$42,$H$25:$H$42<>0,isnumber(find($J25:$J$42,$AR$16)))),""[a-zA-Z ]+.[a-zA-Z ]+""),"""")"),"") | AS17: =IFERROR(__xludf.DUMMYFUNCTION("if(regexmatch(lower(AZ5),""gain proficiency [a-z ]+ choice""), if(isnumber(find("" one "",lower(AZ5))),1,if(isnumber(find("" two "",lower(AZ5))),2,if(isnumber(find("" three "",lower(AZ5))),3,if(isnumber(find("" four "",lower(AZ5))),4,0)))),"""")"),"") | AW17: =IFERROR(__xludf.DUMMYFUNCTION("iferror(textjoin("", "",True, filter($J25:J42, isnumber(find(proper($J$25:$J$42),proper($AW$16)))+ isnumber(find(proper($J$25:$J$42),proper($AW$18))), iserror(find(proper($J$25:$J$42),proper($AQ$16))), if($AS$18>0, iserror(find(proper($J$25:"&"$J$42),proper($AR$16))), iserror(find(proper($J$25:$J$42),proper($AR$17))) ) ) ),"""")"),"")
C18: =if(C20="-","-",INT((C20-10)/2)) -> - | F18: =IFERROR(__xludf.DUMMYFUNCTION("""COMPUTED_VALUE"""),FALSE) -> FALSE | H18: =IFERROR(__xludf.DUMMYFUNCTION("if(or(regexmatch($AQ$63,lower(J18)),regexmatch($AW$16,J18)),1,0)"),0.0) -> 0 | I18: =IFERROR(__xludf.DUMMYFUNCTION("if(and(proficiencyBonus,indirect(left(lower($J18),3)&""Mod"")<>""-""), if($H18<>0,proficiencyBonus,0) +indirect(left(lower($J18),3)&""Mod"") +$AS$58 +sum(arrayformula(int(iferror(substitute(regexextract(lower(filter({BA$32:BA$56;Additional"&"!$BA$3:$BA$24},regexmatch(lower({BA$32:BA$56;Additional!$BA$3:$BA$24}),""[0-9]+ bonus to ""&lower($J18)&"" sav""))),""[0-9]+ bonus to ""&lower($J18)&"" sav""),"" bonus to ""&lower($J18)&"" sav"",""""),0)))),""-"")"),"-") -> - | J18: Dexterity | AQ18: =IFERROR(__xludf.DUMMYFUNCTION("if(race<>"""",if(C15<if(AU24<>""-"",AU24,0),-10,0)+if(isnumber(find(""mobile"",feats)),10,0)+sum(AZ6:AZ15)+sum(arrayformula(int(iferror(trim(left(regexextract(lower(filter({BA$32:BA$56;Additional!$BA$3:$BA$24},regexmatch(lower({BA$32:BA$56;Additional!$BA$"&"3:$BA$24}),""walking speed increases by [0-9]+ feet""))),""[0-9]+ feet""),2)),0)))),"""")"),0.0) -> 0 | AS18: =IFERROR(__xludf.DUMMYFUNCTION("if(race<>"""",counta(iferror(filter(J25:J42,regexmatch(lower(AZ5),""gain proficiency [a-z ]+""&lower(J25:J42)&""[a-z ]+skill"")))),"""")"),0.0) -> 0 | AW18: =IFERROR(__xludf.DUMMYFUNCTION("textjoin("", "",True,arrayformula(if(regexmatch(lower($AW$7:$AW$15),""[0-9] skill""),vlookup($AR$7:$AR$15,'Class Info'!B7:T180,19,False),"""")))"),"")
F19: =IFERROR(__xludf.DUMMYFUNCTION("""COMPUTED_VALUE"""),FALSE) -> FALSE | H19: =IFERROR(__xludf.DUMMYFUNCTION("if(or(regexmatch($AQ$63,lower(J19)),regexmatch($AW$16,J19)),1,0)"),0.0) -> 0 | I19: =IFERROR(__xludf.DUMMYFUNCTION("if(and(proficiencyBonus,indirect(left(lower($J19),3)&""Mod"")<>""-""), if($H19<>0,proficiencyBonus,0) +indirect(left(lower($J19),3)&""Mod"") +$AS$58 +sum(arrayformula(int(iferror(substitute(regexextract(lower(filter({BA$32:BA$56;Additional"&"!$BA$3:$BA$24},regexmatch(lower({BA$32:BA$56;Additional!$BA$3:$BA$24}),""[0-9]+ bonus to ""&lower($J19)&"" sav""))),""[0-9]+ bonus to ""&lower($J19)&"" sav""),"" bonus to ""&lower($J19)&"" sav"",""""),0)))),""-"")"),"-") -> - | J19: Constitution | R19: CURRENT HIT POINTS | AE19: IDEALS | AS19: =IFERROR(__xludf.DUMMYFUNCTION("if(level<>"""",int(iferror(right(regexextract(lower($AW$16),""choose [0-9]""),1),""2""))+sum(arrayformula(iferror(int(regexextract(iferror(regexextract($AW$6:$AW$15,""[0-9] Skill""),""0""),""[0-9]"")),0)),0)+int(iferror(right(regexextract(lower($AW$6),""c"&"hoose [0-9]""),1),""0"")),"""")"),"")
C20: =IFERROR(__xludf.DUMMYFUNCTION("if(C21,min(30,max( iferror(int(trim(right(regexextract(Additional!$AR$79,lower(C17)&""[a-z]+? score is [0-9]+""),2))),0), iferror(int(trim(right(regexextract(Additional!$AR$79,lower(C17)&""[a-z]+? score changes to [0-9]+""),2))),0), min(iferror(int(trim(r"&"ight(regexextract(Additional!$AR$79,lower(C17)&""[a-z]+? [a-z ]+maximum of [0-9]+?""),2))),20), C21+ iferror(if(find(regexextract($AR$5,lower(C17)&"" \+[0-9]""),$AR$5)<iferror(find(""choose"",lower($AR$5)),len($AR$5)),int(right(regexextract($AR$5,lower(C1"&"7)&"" \+[0-9]""),1)),0),0)- iferror(if(find(regexextract($AR$5,lower(C17)&"" \-[0-9]""),$AR$5)<iferror(find(""choose"",lower($AR$5)),len($AR$5)),int(right(regexextract($AR$5,lower(C17)&"" \-[0-9]""),1)),0),0) +D21)) +sum(arrayformula(int(iferror(trim(righ"&"t(regexextract(lower(filter({BA$32:BA$56;Additional!$BA$3:$BA$24},regexmatch(lower({BA$32:BA$56;Additional!$BA$3:$BA$24}),lower(C17)&""[a-z]+? score increases by [0-9]+""))),lower(C17)&""[a-z]+? score increases by [0-9]+""),2)),0))))),""-"")"),"-") -> - | F20: =IFERROR(__xludf.DUMMYFUNCTION("""COMPUTED_VALUE"""),FALSE) -> FALSE | H20: =IFERROR(__xludf.DUMMYFUNCTION("if(or(regexmatch($AQ$63,lower(J20)),regexmatch($AW$16,J20)),1,0)"),0.0) -> 0 | I20: =IFERROR(__xludf.DUMMYFUNCTION("if(and(proficiencyBonus,indirect(left(lower($J20),3)&""Mod"")<>""-""), if($H20<>0,proficiencyBonus,0) +indirect(left(lower($J20),3)&""Mod"") +$AS$58 +sum(arrayformula(int(iferror(substitute(regexextract(lower(filter({BA$32:BA$56;Additional"&"!$BA$3:$BA$24},regexmatch(lower({BA$32:BA$56;Additional!$BA$3:$BA$24}),""[0-9]+ bonus to ""&lower($J20)&"" sav""))),""[0-9]+ bonus to ""&lower($J20)&"" sav""),"" bonus to ""&lower($J20)&"" sav"",""""),0)))),""-"")"),"-") -> - | J20: Intelligence | R20: Condition | AS20: =IFERROR(__xludf.DUMMYFUNCTION("if(counta(iferror(filter(J25:J42,isnumber(find(lower(J25:J42),AQ63)))))=0,"""",counta(iferror(filter(J25:J42,isnumber(find(lower(J25:J42),AQ63))))))"),"")
C21: 0 | F21: =IFERROR(__xludf.DUMMYFUNCTION("""COMPUTED_VALUE"""),FALSE) -> FALSE | H21: =IFERROR(__xludf.DUMMYFUNCTION("if(or(regexmatch($AQ$63,lower(J21)),regexmatch($AW$16,J21)),1,0)"),0.0) -> 0 | I21: =IFERROR(__xludf.DUMMYFUNCTION("if(and(proficiencyBonus,indirect(left(lower($J21),3)&""Mod"")<>""-""), if($H21<>0,proficiencyBonus,0) +indirect(left(lower($J21),3)&""Mod"") +$AS$58 +sum(arrayformula(int(iferror(substitute(regexextract(lower(filter({BA$32:BA$56;Additional"&"!$BA$3:$BA$24},regexmatch(lower({BA$32:BA$56;Additional!$BA$3:$BA$24}),""[0-9]+ bonus to ""&lower($J21)&"" sav""))),""[0-9]+ bonus to ""&lower($J21)&"" sav""),"" bonus to ""&lower($J21)&"" sav"",""""),0)))),""-"")"),"-") -> - | J21: Wisdom
C22: CON | F22: =IFERROR(__xludf.DUMMYFUNCTION("""COMPUTED_VALUE"""),FALSE) -> FALSE | H22: =IFERROR(__xludf.DUMMYFUNCTION("if(or(regexmatch($AQ$63,lower(J22)),regexmatch($AW$16,J22)),1,0)"),0.0) -> 0 | I22: =IFERROR(__xludf.DUMMYFUNCTION("if(and(proficiencyBonus,indirect(left(lower($J22),3)&""Mod"")<>""-""), if($H22<>0,proficiencyBonus,0) +indirect(left(lower($J22),3)&""Mod"") +$AS$58 +sum(arrayformula(int(iferror(substitute(regexextract(lower(filter({BA$32:BA$56;Additional"&"!$BA$3:$BA$24},regexmatch(lower({BA$32:BA$56;Additional!$BA$3:$BA$24}),""[0-9]+ bonus to ""&lower($J22)&"" sav""))),""[0-9]+ bonus to ""&lower($J22)&"" sav""),"" bonus to ""&lower($J22)&"" sav"",""""),0)))),""-"")"),"-") -> - | J22: Charisma
C23: =if(C25="-","-",INT((C25-10)/2)) -> - | F23: =IFERROR(__xludf.DUMMYFUNCTION("""COMPUTED_VALUE"""),FALSE) -> FALSE | H23: SAVING THROWS | R23: TEMPORARY HIT POINTS | AE23: BONDS
F24: =IFERROR(__xludf.DUMMYFUNCTION("arrayformula(if(P24:P42<>"""",P24:P42, if($AC$57<>""EQUIPPED ITEMS"",if(J24:J42<>"""",if(isnumber(find(J24:J42,""AcrobaticsAthleticsSleight of HandStealth"")),""dis"", if(regexmatch(Additional!$AR$79,""advantage on [a-z]+? .""&lower(J24:J42)&"". checks"&"""), if(not(regexmatch(Additional!$AR$79,""advantage on [a-z]+? .""&lower(J24:J42)&"". checks when"")), if(regexmatch(Additional!$AR$79,""sadvantage on [a-z]+ .""&lower(J24:J42)&"". checks""), ""dis"",""adv""),""""), if(J24:J42=""Stealth"",if(lower($A"&"V$24)=""disadvantage"",""dis"",if(lower($AV$24)=""advantage"",""adv"","""")),""""))),""""),"""")))"),"") | K24: =if(countif(H25:H42,"0")=18,"Fill skill bubbles with '1' (one).", if(and(or(RogueLevel>0,BardLevel>2),countif(H25:H42,"e")<1),"Use 'e' for expertise!","") ) -> Fill skill bubbles with '1' (one). | V24: =IMAGE("https://i.imgur.com/k6zj6md.png",2) | W24: =IMAGE("http://i.imgur.com/C5Lv5CM.png",2) | AQ24: =IFERROR(__xludf.DUMMYFUNCTION("iferror(array_constrain(split(textjoin(""~"",True,filter(AQ45:BC56,AQ45:AQ56<>"""",isnumber(find(""armor"",lower(AT45:AT56))))),""~""),1,11),"""")"),"")
C25: =IFERROR(__xludf.DUMMYFUNCTION("if(C26,min(30,max( iferror(int(trim(right(regexextract(Additional!$AR$79,lower(C22)&""[a-z]+? score is [0-9]+""),2))),0), iferror(int(trim(right(regexextract(Additional!$AR$79,lower(C22)&""[a-z]+? score changes to [0-9]+""),2))),0), min(iferror(int(trim(r"&"ight(regexextract(Additional!$AR$79,lower(C22)&""[a-z]+? [a-z ]+maximum of [0-9]+?""),2))),20+if(BarbarianLevel=20,4,0)), C26+if(BarbarianLevel=20,4,0)+ iferror(if(find(regexextract($AR$5,lower(C22)&"" \+[0-9]""),$AR$5)<iferror(find(""choose"",lower($AR$5"&")),len($AR$5)),int(right(regexextract($AR$5,lower(C22)&"" \+[0-9]""),1)),0),0)- iferror(if(find(regexextract($AR$5,lower(C22)&"" \-[0-9]""),$AR$5)<iferror(find(""choose"",lower($AR$5)),len($AR$5)),int(right(regexextract($AR$5,lower(C22)&"" \-[0-9]""),1)),"&"0),0) +D26)) +sum(arrayformula(int(iferror(trim(right(regexextract(lower(filter({BA$32:BA$56;Additional!$BA$3:$BA$24},regexmatch(lower({BA$32:BA$56;Additional!$BA$3:$BA$24}),lower(C22)&""[a-z]+? score increases by [0-9]+""))),lower(C22)&""[a-z]+? score in"&"creases by [0-9]+""),2)),0))))),""-"")"),"-") -> - | F25: =IFERROR(__xludf.DUMMYFUNCTION("""COMPUTED_VALUE"""),"") | H25: 0 | I25: =IFERROR(__xludf.DUMMYFUNCTION("if(and(proficiencyBonus,indirect(regexextract(lower(concatenate(K25:N25)),""[a-z]{3}"")&""Mod"")<>""-""), if(H25<>0,proficiencyBonus*if(H25=""e"",2,1),max(jackOfAllTrades,iferror(if(and(vlookup(""Fighter"",$AR$6:$AS$15,2,false)=""Champion"",FighterLev"&"el>=7),CEILING(proficiencyBonus/2),0),0))) +indirect(regexextract(lower(concatenate(K25:N25)),""[a-z]{3}"")&""Mod"") +$AR$58 +sum(arrayformula(int(iferror(trim(left(regexextract(lower(filter({BA$32:BA$56;Additional!$BA$3:$BA$24},regexmatch(low"&"er({BA$32:BA$56;Additional!$BA$3:$BA$24}),""[0-9]+ bonus to ""&regexextract(lower(concatenate(K25:N25)),""[a-z]{3}"")&""[a-z]+? .""&lower(J25)))),""[0-9]+ bonus to ""&regexextract(lower(concatenate(K25:N25)),""[a-z]{3}"")&""[a-z]+? .""&lower(J25)),2)),0))"&")),""-"")"),"-") -> - | J25: Acrobatics | M25: (Dex) | R25: =IFERROR(__xludf.DUMMYFUNCTION("iferror(textjoin("" "",true,arrayformula(sumif($AQ$6:$AQ$15,arrayformula(""d""&sort(unique(filter(int(regexextract(AQ6:AQ15,""[0-9]+"")),AQ6:AQ15<>"""")),1,True)),AT6:AT15)&arrayformula(""d""&sort(unique(filter(int(regexextract(AQ6:AQ15,""[0-9]+"")),AQ6:A"&"Q15<>"""")),1,True)))),""-"")"),"-") -> - | X25: SUC. | Y25: 0 | Z25: 0 | AA25: 0 | AQ25: =IFERROR(__xludf.DUMMYFUNCTION("iferror(array_constrain(split(textjoin(""~"",True,filter(AQ45:BC56,AQ45:AQ56<>"""",isnumber(find(""shield"",lower(AT45:AT56))))),""~""),1,11),"""")"),"")
C26: 0 | F26: =IFERROR(__xludf.DUMMYFUNCTION("""COMPUTED_VALUE"""),"") | H26: 0 | I26: =IFERROR(__xludf.DUMMYFUNCTION("if(and(proficiencyBonus,indirect(regexextract(lower(concatenate(K26:N26)),""[a-z]{3}"")&""Mod"")<>""-""), if(H26<>0,proficiencyBonus*if(H26=""e"",2,1),jackOfAllTrades) +indirect(regexextract(lower(concatenate(K26:N26)),""[a-z]{3}"")&""Mod"") +"&"$AR$58 +sum(arrayformula(int(iferror(trim(left(regexextract(lower(filter({BA$32:BA$56;Additional!$BA$3:$BA$24},regexmatch(lower({BA$32:BA$56;Additional!$BA$3:$BA$24}),""[0-9]+ bonus to ""&regexextract(lower(concatenate(K26:N26)),""[a-z]{3}"")&""[a-z]+"&"? .""&lower(J26)))),""[0-9]+ bonus to ""&regexextract(lower(concatenate(K26:N26)),""[a-z]{3}"")&""[a-z]+? .""&lower(J26)),2)),0)))),""-"")"),"-") -> - | J26: Animal Handling | N26: (Wis) | X26: FAIL. | Y26: 0 | Z26: 0 | AA26: 0 | AQ26: =IFERROR(__xludf.DUMMYFUNCTION("if(level="""","""", if(isnumber($AS$5),$AS$5,10+AR24+if(AW24<>""-"",AW24,0)+defense+mariner+min(if(AS24=""-"",dexMod,AS24),max(if(AS24<>0,dexMod,AS24),dexMod)) +if(regexmatch($AS$5,""\+[0-9]""), if(isnumber(find(""Heavy"",$AS$5)), if(is"&"number(find(""NoHeavy"",$AS$5)), if(isnumber(find(""heavy"",lower($AT$24))),0,int(regexextract($AS$5,""\+[0-9]""))), if(iserror(find(""heavy"",lower($AT$24))),0,int(regexextract($AS$5,""\+[0-9]"")))),int(regexextract($AS$5,""\+[0-9]"")"&")),0) +if(regexmatch($BC$5,""\+[0-9]""), if(isnumber(find(""Heavy"",$BC$5)), if(isnumber(find(""NoHeavy"",$BC$5)), if(isnumber(find(""heavy"",lower($AT$24))),0,int(regexextract($BC$5,""\+[0-9]""))), if(iserror(find(""hea"&"vy"",lower($AT$24))),0,int(regexextract($BC$5,""\+[0-9]"")))),int(regexextract($BC$5,""\+[0-9]""))),0) +AR25+if(AW25<>""-"",AW25,0) +sum(filter(AR45:AR56,iserror(find(""no armor"",BA45:BA56)),AT45:AT56<>""Shield"",not(isnumber(find(""armor"",lower"&"(AT45:AT56)))))) +iferror(sum(arrayformula(vlookup(filter((split($BC$5,""+"")),isnumber(find(split($BC$5,""+""),""halfDexhalfConhalfInthalfWishalfChahalfStr""))),{""halfDex"",max(floor(dexMod/2),1);""halfCon"",max(floor(conMod/2),1);""halfInt"",max(fl"&"oor(intMod/2),1);""halfWis"",max(floor(wisMod/2),1);""halfCha"",max(floor(chaMod/2),1);""halfStr"",max(floor(strMod/2),1)},2,false)))) ))"),"") | AR26: =IFERROR(__xludf.DUMMYFUNCTION("if(or(level="""",race="""",dexMod=""-""),"""", if(iserror(find(""+"",$BC$5)),$BC$5+if(and(AQ24="""",isnumber(find(""armor of shadows"",lower(AQ61)))),3,0), if($BC$5<>""10+dex"", int(regexextract($BC$5,""[0-9]+"")) +sum(arrayformula(vloo"&"kup(filter((split($BC$5,""+"")),isnumber(find(lower(split($BC$5,""+"")),""halfdexhalfconhalfinthalfwishalfchahalfstr""))),{""dex"",dexMod;""con"",conMod;""int"",intMod;""wis"",wisMod;""cha"",chaMod;""str"",strMod;""halfDex"",max(floor(dexMod/2),1);""halfC"&"on"",max(floor(conMod/2),1);""halfInt"",max(floor(intMod/2),1);""halfWis"",max(floor(wisMod/2),1);""halfCha"",max(floor(chaMod/2),1);""halfStr"",max(floor(strMod/2),1)},2,false))) +if(not(isnumber($AS$5)),if(regexmatch($AS$5,""\+[0-9]""), "&" if(isnumber(find(""Heavy"",$AS$5)), if(isnumber(find(""NoHeavy"",$AS$5)), if(isnumber(find(""heavy"",lower($AT$24))),0,int(regexextract($AS$5,""\+[0-9]""))), if(iserror(find(""heavy"",lower($AT$24))),0,int(regex"&"extract($AS$5,""\+[0-9]"")))),int(regexextract($AS$5,""\+[0-9]""))),0),0) +if(regexmatch($BC$5,""\+[0-9]""), if(isnumber(find(""Heavy"",$BC$5)), if(isnumber(find(""NoHeavy"",$BC$5)), if(isnumber(find(""heavy"""&",lower($AT$24))),0,int(regexextract($BC$5,""\+[0-9]""))), if(iserror(find(""heavy"",lower($AT$24))),0,int(regexextract($BC$5,""\+[0-9]"")))),int(regexextract($BC$5,""\+[0-9]""))),0), 10+dexMod+if(and(AQ24="""",isnumber(find(""armor of sh"&"adows"",lower(AQ61)))),3,0))) +sum(filter(AR45:AR56,lower(AT45:AT56)<>""shield"",if(isnumber(find(""no armor"",lower(BA45:BA56))),AQ24="""",1),if(isnumber(find(""no shield"",lower(BA45:BA56))),AQ25="""",1),not(isnumber(find(""armor"",lower(AT45:AT56)))))"&") +AR25+if(AW25<>""-"",AW25,0))"),"") | AS26: =IFERROR(__xludf.DUMMYFUNCTION("if(or(level="""",race="""",dexMod=""-""),"""", if(isnumber($AS$5),$AS$5,if($AS$5<>""-"", int(regexextract($AS$5,""[0-9]+"")) +sum(arrayformula(vlookup(filter((split($AS$5,""+"")),isnumber(find(split($AS$5,""+""),""dexconintwischastr""))),{""de"&"x"",dexMod;""con"",conMod;""int"",intMod;""wis"",wisMod;""cha"",chaMod;""str"",strMod},2,false))) +iferror(sum(arrayformula(vlookup(filter((split($BC$5,""+"")),isnumber(find(split($BC$5,""+""),""halfDexhalfConhalfInthalfWishalfChahalfStr""))),{""halfD"&"ex"",max(floor(dexMod/2),1);""halfCon"",max(floor(conMod/2),1);""halfInt"",max(floor(intMod/2),1);""halfWis"",max(floor(wisMod/2),1);""halfCha"",max(floor(chaMod/2),1);""halfStr"",max(floor(strMod/2),1)},2,false))),0) +if(regexmatch($AS$5,""\+[0-9]"")"&", if(isnumber(find(""Heavy"",$AS$5)), if(isnumber(find(""NoHeavy"",$AS$5)), if(isnumber(find(""heavy"",lower($AT$24))),0,int(regexextract($AS$5,""\+[0-9]""))), if(iserror(find(""heavy"",lower($AT$24))),0,int(regexextract($AS"&"$5,""\+[0-9]"")))),int(regexextract($AS$5,""\+[0-9]""))),0), 10+dexMod )) +sum(filter(AR45:AR56,lower(AT45:AT56)<>""shield"",if(isnumber(find(""no armor"",lower(BA45:BA56))),AQ24="""",1),if(isnumber(find(""no shield"",lower(BA45:BA56))),AQ25="""",1)"&",not(isnumber(find(""armor"",lower(AT45:AT56)))))) +AR25+if(AW25<>""-"",AW25,0))"),"") | AT26: =IFERROR(__xludf.DUMMYFUNCTION("if(or(level="""",race="""",dexMod=""-""),"""", if(isnumber($BA$16),$BA$16,if($BA$16<>""-"", int(regexextract($BA$16,""[0-9]+"")) +sum(arrayformula(vlookup(filter((split($BA$16,""+"")),isnumber(find(split($BA$16,""+""),""dexconintwischastr"")))"&",{""dex"",dexMod;""con"",conMod;""int"",intMod;""wis"",wisMod;""cha"",chaMod;""str"",strMod},2,false))) +iferror(sum(arrayformula(vlookup(filter((split($BC$5,""+"")),isnumber(find(split($BC$5,""+""),""halfDexhalfConhalfInthalfWishalfChahalfStr""))),{"&"""halfDex"",max(floor(dexMod/2),1);""halfCon"",max(floor(conMod/2),1);""halfInt"",max(floor(intMod/2),1);""halfWis"",max(floor(wisMod/2),1);""halfCha"",max(floor(chaMod/2),1);""halfStr"",max(floor(strMod/2),1)},2,false))),0) +if(regexmatch($BA$16,""\+"&"[0-9]""), if(isnumber(find(""Heavy"",$BA$16)), if(isnumber(find(""NoHeavy"",$BA$16)), if(isnumber(find(""heavy"",lower($AT$24))),0,int(regexextract($BA$16,""\+[0-9]""))), if(iserror(find(""heavy"",lower($AT$24))),0,int(regex"&"extract($BA$16,""\+[0-9]"")))),int(regexextract($BA$16,""\+[0-9]""))),0), 10+dexMod )) +sum(filter(AR45:AR56,lower(AT45:AT56)<>""shield"",if(isnumber(find(""no armor"",lower(BA45:BA56))),AQ24="""",1),if(isnumber(find(""no shield"",lower(BA45:BA56)))"&",AQ25="""",1),not(isnumber(find(""armor"",lower(AT45:AT56)))))) +AR25+if(AW25<>""-"",AW25,0))"),"") | AY26: =IFERROR(__xludf.DUMMYFUNCTION("iferror(sum(arrayformula(int(substitute(regexextract(lower(filter(unique({BA32:BA36;Additional!BA3:BA24}),regexmatch(lower(unique({BA32:BA36;Additional!BA3:BA24})),""[0-9]+ bonus to ability checks""))),""[0-9]+ bonus to ability checks""),"" bonus to abili"&"ty checks"","""")))),"""")"),"") | AZ26: =IFERROR(__xludf.DUMMYFUNCTION("iferror(sum(arrayformula(int(substitute(regexextract(lower(filter(unique({BA32:BA36;Additional!BA3:BA24}),regexmatch(lower(unique({BA32:BA36;Additional!BA3:BA24})),""[0-9]+ bonus to saving throws""))),""[0-9]+ bonus to saving throws""),"" bonus to saving "&"throws"","""")))),"""")"),"")
C27: INT | F27: =IFERROR(__xludf.DUMMYFUNCTION("""COMPUTED_VALUE"""),"") | H27: 0 | I27: =IFERROR(__xludf.DUMMYFUNCTION("if(and(proficiencyBonus,indirect(regexextract(lower(concatenate(K27:N27)),""[a-z]{3}"")&""Mod"")<>""-""), if(H27<>0,proficiencyBonus*if(H27=""e"",2,1),jackOfAllTrades) +indirect(regexextract(lower(concatenate(K27:N27)),""[a-z]{3}"")&""Mod"") +"&"$AR$58 +sum(arrayformula(int(iferror(trim(left(regexextract(lower(filter({BA$32:BA$56;Additional!$BA$3:$BA$24},regexmatch(lower({BA$32:BA$56;Additional!$BA$3:$BA$24}),""[0-9]+ bonus to ""&regexextract(lower(concatenate(K27:N27)),""[a-z]{3}"")&""[a-z]+"&"? .""&lower(J27)))),""[0-9]+ bonus to ""&regexextract(lower(concatenate(K27:N27)),""[a-z]{3}"")&""[a-z]+? .""&lower(J27)),2)),0)))),""-"")"),"-") -> - | J27: Arcana | L27: (Int) | R27: HIT DICE | X27: =if(AND(Y26<>0,Z26<>0,AA26<>0),"DEAD",if(AND(Y25<>0,Z25<>0,AA25<>0),"STABLE","DEATH SAVES")) -> DEATH SAVES | AE27: FLAWS
C28: =if(C30="-","-",INT((C30-10)/2)) -> - | F28: =IFERROR(__xludf.DUMMYFUNCTION("""COMPUTED_VALUE"""),"") | H28: 0 | I28: =IFERROR(__xludf.DUMMYFUNCTION("if(and(proficiencyBonus,indirect(regexextract(lower(concatenate(K28:N28)),""[a-z]{3}"")&""Mod"")<>""-""), if(H28<>0,proficiencyBonus*if(H28=""e"",2,1),max(jackOfAllTrades,iferror(if(and(vlookup(""Fighter"",$AR$6:$AS$15,2,false)=""Champion"",FighterLev"&"el>=7),CEILING(proficiencyBonus/2),0),0))) +indirect(regexextract(lower(concatenate(K28:N28)),""[a-z]{3}"")&""Mod"") +$AR$58 +sum(arrayformula(int(iferror(trim(left(regexextract(lower(filter({BA$32:BA$56;Additional!$BA$3:$BA$24},regexmatch(low"&"er({BA$32:BA$56;Additional!$BA$3:$BA$24}),""[0-9]+ bonus to ""&regexextract(lower(concatenate(K28:N28)),""[a-z]{3}"")&""[a-z]+? .""&lower(J28)))),""[0-9]+ bonus to ""&regexextract(lower(concatenate(K28:N28)),""[a-z]{3}"")&""[a-z]+? .""&lower(J28)),2)),0))"&")),""-"")"),"-") -> - | J28: Athletics | M28: (Str) | AE28: ALIGNMENT:
F29: =IFERROR(__xludf.DUMMYFUNCTION("""COMPUTED_VALUE"""),"") | H29: 0 | I29: =IFERROR(__xludf.DUMMYFUNCTION("if(and(proficiencyBonus,indirect(regexextract(lower(concatenate(K29:N29)),""[a-z]{3}"")&""Mod"")<>""-""), if(H29<>0,proficiencyBonus*if(H29=""e"",2,1),jackOfAllTrades) +indirect(regexextract(lower(concatenate(K29:N29)),""[a-z]{3}"")&""Mod"") +"&"$AR$58 +sum(arrayformula(int(iferror(trim(left(regexextract(lower(filter({BA$32:BA$56;Additional!$BA$3:$BA$24},regexmatch(lower({BA$32:BA$56;Additional!$BA$3:$BA$24}),""[0-9]+ bonus to ""&regexextract(lower(concatenate(K29:N29)),""[a-z]{3}"")&""[a-z]+"&"? .""&lower(J29)))),""[0-9]+ bonus to ""&regexextract(lower(concatenate(K29:N29)),""[a-z]{3}"")&""[a-z]+? .""&lower(J29)),2)),0)))),""-"")"),"-") -> - | J29: Deception | M29: (Cha) | Q29: =IMAGE("https://i.imgur.com/pxrdqMy.png",2) | AD29: =IMAGE("https://i.imgur.com/pxrdqMy.png",2)
C30: =IFERROR(__xludf.DUMMYFUNCTION("if(C31,min(30,max( iferror(int(trim(right(regexextract(Additional!$AR$79,lower(C27)&""[a-z]+? score is [0-9]+""),2))),0), iferror(int(trim(right(regexextract(Additional!$AR$79,lower(C27)&""[a-z]+? score changes to [0-9]+""),2))),0), min(iferror(int(trim(r"&"ight(regexextract(Additional!$AR$79,lower(C27)&""[a-z]+? [a-z ]+maximum of [0-9]+?""),2))),20), C31+ iferror(if(find(regexextract($AR$5,lower(C27)&"" \+[0-9]""),$AR$5)<iferror(find(""choose"",lower($AR$5)),len($AR$5)),int(right(regexextract($AR$5,lower(C2"&"7)&"" \+[0-9]""),1)),0),0)- iferror(if(find(regexextract($AR$5,lower(C27)&"" \-[0-9]""),$AR$5)<iferror(find(""choose"",lower($AR$5)),len($AR$5)),int(right(regexextract($AR$5,lower(C27)&"" \-[0-9]""),1)),0),0) +D31)) +sum(arrayformula(int(iferror(trim(righ"&"t(regexextract(lower(filter({BA$32:BA$56;Additional!$BA$3:$BA$24},regexmatch(lower({BA$32:BA$56;Additional!$BA$3:$BA$24}),lower(C27)&""[a-z]+? score increases by [0-9]+""))),lower(C27)&""[a-z]+? score increases by [0-9]+""),2)),0))))),""-"")"),"-") -> - | F30: =IFERROR(__xludf.DUMMYFUNCTION("""COMPUTED_VALUE"""),"") | H30: 0 | I30: =IFERROR(__xludf.DUMMYFUNCTION("if(and(proficiencyBonus,indirect(regexextract(lower(concatenate(K30:N30)),""[a-z]{3}"")&""Mod"")<>""-""), if(H30<>0,proficiencyBonus*if(H30=""e"",2,1),jackOfAllTrades) +indirect(regexextract(lower(concatenate(K30:N30)),""[a-z]{3}"")&""Mod"") +"&"$AR$58 +sum(arrayformula(int(iferror(trim(left(regexextract(lower(filter({BA$32:BA$56;Additional!$BA$3:$BA$24},regexmatch(lower({BA$32:BA$56;Additional!$BA$3:$BA$24}),""[0-9]+ bonus to ""&regexextract(lower(concatenate(K30:N30)),""[a-z]{3}"")&""[a-z]+"&"? .""&lower(J30)))),""[0-9]+ bonus to ""&regexextract(lower(concatenate(K30:N30)),""[a-z]{3}"")&""[a-z]+? .""&lower(J30)),2)),0)))),""-"")"),"-") -> - | J30: History | L30: (Int) | Q30: =IMAGE("https://i.imgur.com/AaGmGAX.png",4, 608, 20) | AO30: =image("https://i.imgur.com/H6Xrt2L.png",4, 1196, 20)
C31: 0 | F31: =IFERROR(__xludf.DUMMYFUNCTION("""COMPUTED_VALUE"""),"") | H31: 0 | I31: =IFERROR(__xludf.DUMMYFUNCTION("if(and(proficiencyBonus,indirect(regexextract(lower(concatenate(K31:N31)),""[a-z]{3}"")&""Mod"")<>""-""), if(H31<>0,proficiencyBonus*if(H31=""e"",2,1),jackOfAllTrades) +indirect(regexextract(lower(concatenate(K31:N31)),""[a-z]{3}"")&""Mod"") +"&"$AR$58 +sum(arrayformula(int(iferror(trim(left(regexextract(lower(filter({BA$32:BA$56;Additional!$BA$3:$BA$24},regexmatch(lower({BA$32:BA$56;Additional!$BA$3:$BA$24}),""[0-9]+ bonus to ""&regexextract(lower(concatenate(K31:N31)),""[a-z]{3}"")&""[a-z]+"&"? .""&lower(J31)))),""[0-9]+ bonus to ""&regexextract(lower(concatenate(K31:N31)),""[a-z]{3}"")&""[a-z]+? .""&lower(J31)),2)),0)))),""-"")"),"-") -> - | J31: Insight | L31: (Wis) | R31: NAME | Y31: ATK BONUS | AC31: DAMAGE/TYPE
C32: WIS | F32: =IFERROR(__xludf.DUMMYFUNCTION("""COMPUTED_VALUE"""),"") | H32: 0 | I32: =IFERROR(__xludf.DUMMYFUNCTION("if(and(proficiencyBonus,indirect(regexextract(lower(concatenate(K32:N32)),""[a-z]{3}"")&""Mod"")<>""-""), if(H32<>0,proficiencyBonus*if(H32=""e"",2,1),jackOfAllTrades) +indirect(regexextract(lower(concatenate(K32:N32)),""[a-z]{3}"")&""Mod"") +"&"$AR$58 +sum(arrayformula(int(iferror(trim(left(regexextract(lower(filter({BA$32:BA$56;Additional!$BA$3:$BA$24},regexmatch(lower({BA$32:BA$56;Additional!$BA$3:$BA$24}),""[0-9]+ bonus to ""&regexextract(lower(concatenate(K32:N32)),""[a-z]{3}"")&""[a-z]+"&"? .""&lower(J32)))),""[0-9]+ bonus to ""&regexextract(lower(concatenate(K32:N32)),""[a-z]{3}"")&""[a-z]+? .""&lower(J32)),2)),0)))),""-"")"),"-") -> - | J32: Intimidation | M32: (Cha) | X32: =IMAGE("http://i.imgur.com/qlVxTyw.png",3) | Y32: =IFERROR(__xludf.DUMMYFUNCTION("if(and(proficiencyBonus,$AQ32<>"""",$BC32<>""-""), if(or( isnumber(find(""unarmed"",lower($AT32))), isnumber(find(""natural"",lower($AT32))), isnumber(find(""spell"",lower($AT32))), and(isnum"&"ber(find(""improvised"",lower($AQ32))),isnumber(find(""brawler"",feats))), isnumber(find(lower($AT32),lower(weaponProficiencies))), not(isna(filter(arrayformula(trim(split(lower(weaponProficiencies),"",""))),isnumber(find(array"&"formula(trim(split(lower(weaponProficiencies),"",""))),lower($AQ32)))))) ), proficiencyBonus, 0 ) +if(lower($AU32)=""ranged"",archery+closeQuarters,0) +if(isnumber(find(""spell"",lower($AT32))),v2.1"&"!$AR$91,0) +$BC32, ""-"" )"),"-") -> - | AB32: =IMAGE("http://i.imgur.com/qlVxTyw.png",3) | AC32: =IFERROR(__xludf.DUMMYFUNCTION("substitute(if(and($AQ32<>"""",proficiencyBonus<>""""), $AR32&if(and(""melee""=lower($AU32),lower($AT32)<>""unarmed"",isnumber(find(""two-handed"",lower($R32&$BA32)))),greatWeaponFighting,"""") &if($AR32<>0,""+"" &if($BB32<>""〇"",$BC32,if($AW32<>""-"",$AW"&"32,0)) +int(iferror(regexextract(regexextract(Additional!$AR$79,""proficiency with[a-z ]+""&lower(array_constrain(filter('Attack Info'!$B$7:$B180,'Attack Info'!$B$7:$B180<>"""",isnumber(find(lower('Attack Info'!$B$7:$B180),lower($AQ32)))),1,1))&""[a-z, ]+"&"\+[0-9]+ bonus to damage[a-z ]+with such weapons""),""[0-9]+?""),0)) +int(iferror(regexextract(regexextract(Additional!$AR$79,""\+[0-9] bonus to damage[a-z ]+""&lower(array_constrain(filter('Attack Info'!$B$7:$B180,'Attack Info'!$B$7:$B180<>"""",isnumber("&"find(lower('Attack Info'!$B$7:$B180),lower($AQ32)))),1,1))),""[0-9]+?""),0)) +if(and(isnumber(find(""melee"",lower($AU32))),iserror(find(""unarmed"",lower($AT32))),iserror(find(""natural"",lower($AT32))),iserror(find(""two-handed"",lower($R32&$BA32)))),du"&"eling,0) +if(isnumber(find(""thrown"",lower($BA32))),thrown,0) &""[""&$AS32&""]"","""") &if(and(PaladinLevel>=11,isnumber(find(""melee"",lower($AU32))),isnumber(find(lower($AT32),""simplemartial""))),""+1d8[radiant]"","""") &if($AX32<>""-"",""+""&$AX32&"""&"[""&$AY32&""]"","""") &if(and(isnumber(find(""pact"",lower($AQ32))),isnumber(find(""lifedrinker"",lower(invocations)))),""+""&chaMod&""[necrotic]"","""") &""|***""&textjoin("" "",True,if(and($AT32<>""-"",$AT32<>""Spell""),$AT32,""""),if($AU32<>""-"",$AU32"&",""""),if($AT32=""Spell"",$AT32,if(and($AT32<>""Unarmed"",$AT32<>""Natural""),""Weapon"","""")))&"" Attack.***"" &if($BA32<>""-"","" ""&$BA32,"""") &if(and(isnumber(find(""melee"",lower($AU32))),iserror(find(""unarmed"",lower($AT32))),iserror(find(""natur"&"al"",lower($AT32))),iserror(find(""two-handed"",lower($R32&$AV32)))),"" ""&duelingText,"""") &if(and(or(lower($AT32)=""unarmed"",lower($AT32)=""natural""),unarmedFighting),"" ""&unarmedText,"""") &if(and(""melee""=lower($AU32),lower($AT32)<>""unarmed"",is"&"number(find(""two-handed"",lower($R32&$BA32)))),"" ""&gwfText,"""") &if(and(isnumber(find(""offhand"",lower($R32))),twoWeaponFighting),"" ""&twfText,"""") &if(and(lower($AU32)=""ranged"",lower($AT32)<>""spell""),if(archeryText<>"""","" ""&archeryText,"""""&")&if(closeQuartersText<>"""","" ""&closeQuartersText,""""),"""") &if(isnumber(find(""thrown"",lower($BA32))),"" ""&thrownText,""""),"" -""),""+0"","""")")," -") -> - | AQ32: =IFERROR(__xludf.DUMMYFUNCTION("iferror(array_constrain(split(textjoin(""~"",True,filter('Attack Info'!$B$7:$AN180,'Attack Info'!$B$7:$B180<>"""",lower('Attack Info'!$B$7:$B180)=lower(R32))),""~""),1,12),"""")"),"") | BC32: {=if(and(strMod<>"-",dexMod<>"-"),if($AQ32<>"",if($AW32<>"-",$AW32,0) +if(isnumber(find(lower($AZ32),"strdexconintwischa")),if(indirect(lower($AZ32)&"Mod")<>"-",indirect(lower($AZ32)&"Mod"),0), if(or(isnumber(find("finesse",lower($BA32))),and($AV32<>"〇",MonkLevel<>"",MonkLevel>0)),max(strMod,dexMod),if(lower($AU32)="ranged",dexMod,strMod))),""),"-")} -> -
C33: =if(C35="-","-",INT((C35-10)/2)) -> - | F33: =IFERROR(__xludf.DUMMYFUNCTION("""COMPUTED_VALUE"""),"") | H33: 0 | I33: =IFERROR(__xludf.DUMMYFUNCTION("if(and(proficiencyBonus,indirect(regexextract(lower(concatenate(K33:N33)),""[a-z]{3}"")&""Mod"")<>""-""), if(H33<>0,proficiencyBonus*if(H33=""e"",2,1),jackOfAllTrades) +indirect(regexextract(lower(concatenate(K33:N33)),""[a-z]{3}"")&""Mod"") +"&"$AR$58 +sum(arrayformula(int(iferror(trim(left(regexextract(lower(filter({BA$32:BA$56;Additional!$BA$3:$BA$24},regexmatch(lower({BA$32:BA$56;Additional!$BA$3:$BA$24}),""[0-9]+ bonus to ""&regexextract(lower(concatenate(K33:N33)),""[a-z]{3}"")&""[a-z]+"&"? .""&lower(J33)))),""[0-9]+ bonus to ""&regexextract(lower(concatenate(K33:N33)),""[a-z]{3}"")&""[a-z]+? .""&lower(J33)),2)),0)))),""-"")"),"-") -> - | J33: Investigation | M33: (Int) | X33: =IMAGE("http://i.imgur.com/qlVxTyw.png",3) | Y33: =IFERROR(__xludf.DUMMYFUNCTION("if(and(proficiencyBonus,$AQ33<>"""",$BC33<>""-""), if(or( isnumber(find(""unarmed"",lower($AT33))), isnumber(find(""natural"",lower($AT33))), isnumber(find(""spell"",lower($AT33))), and(isnum"&"ber(find(""improvised"",lower($AQ33))),isnumber(find(""brawler"",feats))), isnumber(find(lower($AT33),lower(weaponProficiencies))), not(isna(filter(arrayformula(trim(split(lower(weaponProficiencies),"",""))),isnumber(find(array"&"formula(trim(split(lower(weaponProficiencies),"",""))),lower($AQ33)))))) ), proficiencyBonus, 0 ) +if(lower($AU33)=""ranged"",archery+closeQuarters,0) +if(isnumber(find(""spell"",lower($AT33))),v2.1"&"!$AR$91,0) +$BC33, ""-"" )"),"-") -> - | AB33: =IMAGE("http://i.imgur.com/qlVxTyw.png",3) | AC33: =IFERROR(__xludf.DUMMYFUNCTION("substitute(if(and($AQ33<>"""",proficiencyBonus<>""""), $AR33&if(and(""melee""=lower($AU33),lower($AT33)<>""unarmed"",isnumber(find(""two-handed"",lower($R33&$BA33)))),greatWeaponFighting,"""") &if($AR33<>0,""+"" &if($BB33<>""〇"",$BC33,if($AW33<>""-"",$AW"&"33,0)) +int(iferror(regexextract(regexextract(Additional!$AR$79,""proficiency with[a-z ]+""&lower(array_constrain(filter('Attack Info'!$B$7:$B180,'Attack Info'!$B$7:$B180<>"""",isnumber(find(lower('Attack Info'!$B$7:$B180),lower($AQ33)))),1,1))&""[a-z, ]+"&"\+[0-9]+ bonus to damage[a-z ]+with such weapons""),""[0-9]+?""),0)) +int(iferror(regexextract(regexextract(Additional!$AR$79,""\+[0-9] bonus to damage[a-z ]+""&lower(array_constrain(filter('Attack Info'!$B$7:$B180,'Attack Info'!$B$7:$B180<>"""",isnumber("&"find(lower('Attack Info'!$B$7:$B180),lower($AQ33)))),1,1))),""[0-9]+?""),0)) +if(and(isnumber(find(""melee"",lower($AU33))),iserror(find(""unarmed"",lower($AT33))),iserror(find(""natural"",lower($AT33))),iserror(find(""two-handed"",lower($R33&$BA33)))),du"&"eling,0) +if(isnumber(find(""thrown"",lower($BA33))),thrown,0) &""[""&$AS33&""]"","""") &if(and(PaladinLevel>=11,isnumber(find(""melee"",lower($AU33))),isnumber(find(lower($AT33),""simplemartial""))),""+1d8[radiant]"","""") &if($AX33<>""-"",""+""&$AX33&"""&"[""&$AY33&""]"","""") &if(and(isnumber(find(""pact"",lower($AQ33))),isnumber(find(""lifedrinker"",lower(invocations)))),""+""&chaMod&""[necrotic]"","""") &""|***""&textjoin("" "",True,if(and($AT33<>""-"",$AT33<>""Spell""),$AT33,""""),if($AU33<>""-"",$AU33"&",""""),if($AT33=""Spell"",$AT33,if(and($AT33<>""Unarmed"",$AT33<>""Natural""),""Weapon"","""")))&"" Attack.***"" &if($BA33<>""-"","" ""&$BA33,"""") &if(and(isnumber(find(""melee"",lower($AU33))),iserror(find(""unarmed"",lower($AT33))),iserror(find(""natur"&"al"",lower($AT33))),iserror(find(""two-handed"",lower($R33&$AV33)))),"" ""&duelingText,"""") &if(and(or(lower($AT33)=""unarmed"",lower($AT33)=""natural""),unarmedFighting),"" ""&unarmedText,"""") &if(and(""melee""=lower($AU33),lower($AT33)<>""unarmed"",is"&"number(find(""two-handed"",lower($R33&$BA33)))),"" ""&gwfText,"""") &if(and(isnumber(find(""offhand"",lower($R33))),twoWeaponFighting),"" ""&twfText,"""") &if(and(lower($AU33)=""ranged"",lower($AT33)<>""spell""),if(archeryText<>"""","" ""&archeryText,"""""&")&if(closeQuartersText<>"""","" ""&closeQuartersText,""""),"""") &if(isnumber(find(""thrown"",lower($BA33))),"" ""&thrownText,""""),"" -""),""+0"","""")")," -") -> - | AQ33: =IFERROR(__xludf.DUMMYFUNCTION("iferror(array_constrain(split(textjoin(""~"",True,filter('Attack Info'!$B$7:$AN180,'Attack Info'!$B$7:$B180<>"""",lower('Attack Info'!$B$7:$B180)=lower(R33))),""~""),1,12),"""")"),"") | BC33: {=if(and(strMod<>"-",dexMod<>"-"),if($AQ33<>"",if($AW33<>"-",$AW33,0) +if(isnumber(find(lower($AZ33),"strdexconintwischa")),if(indirect(lower($AZ33)&"Mod")<>"-",indirect(lower($AZ33)&"Mod"),0), if(or(isnumber(find("finesse",lower($BA33))),and($AV33<>"〇",MonkLevel<>"",MonkLevel>0)),max(strMod,dexMod),if(lower($AU33)="ranged",dexMod,strMod))),""),"-")} -> -
F34: =IFERROR(__xludf.DUMMYFUNCTION("""COMPUTED_VALUE"""),"") | H34: 0 | I34: =IFERROR(__xludf.DUMMYFUNCTION("if(and(proficiencyBonus,indirect(regexextract(lower(concatenate(K34:N34)),""[a-z]{3}"")&""Mod"")<>""-""), if(H34<>0,proficiencyBonus*if(H34=""e"",2,1),jackOfAllTrades) +indirect(regexextract(lower(concatenate(K34:N34)),""[a-z]{3}"")&""Mod"") +"&"$AR$58 +sum(arrayformula(int(iferror(trim(left(regexextract(lower(filter({BA$32:BA$56;Additional!$BA$3:$BA$24},regexmatch(lower({BA$32:BA$56;Additional!$BA$3:$BA$24}),""[0-9]+ bonus to ""&regexextract(lower(concatenate(K34:N34)),""[a-z]{3}"")&""[a-z]+"&"? .""&lower(J34)))),""[0-9]+ bonus to ""&regexextract(lower(concatenate(K34:N34)),""[a-z]{3}"")&""[a-z]+? .""&lower(J34)),2)),0)))),""-"")"),"-") -> - | J34: Medicine | M34: (Wis) | X34: =IMAGE("http://i.imgur.com/qlVxTyw.png",3) | Y34: =IFERROR(__xludf.DUMMYFUNCTION("if(and(proficiencyBonus,$AQ34<>"""",$BC34<>""-""), if(or( isnumber(find(""unarmed"",lower($AT34))), isnumber(find(""natural"",lower($AT34))), isnumber(find(""spell"",lower($AT34))), and(isnum"&"ber(find(""improvised"",lower($AQ34))),isnumber(find(""brawler"",feats))), isnumber(find(lower($AT34),lower(weaponProficiencies))), not(isna(filter(arrayformula(trim(split(lower(weaponProficiencies),"",""))),isnumber(find(array"&"formula(trim(split(lower(weaponProficiencies),"",""))),lower($AQ34)))))) ), proficiencyBonus, 0 ) +if(lower($AU34)=""ranged"",archery+closeQuarters,0) +if(isnumber(find(""spell"",lower($AT34))),v2.1"&"!$AR$91,0) +$BC34, ""-"" )"),"-") -> - | AB34: =IMAGE("http://i.imgur.com/qlVxTyw.png",3) | AC34: =IFERROR(__xludf.DUMMYFUNCTION("substitute(if(and($AQ34<>"""",proficiencyBonus<>""""), $AR34&if(and(""melee""=lower($AU34),lower($AT34)<>""unarmed"",isnumber(find(""two-handed"",lower($R34&$BA34)))),greatWeaponFighting,"""") &if($AR34<>0,""+"" &if($BB34<>""〇"",$BC34,if($AW34<>""-"",$AW"&"34,0)) +int(iferror(regexextract(regexextract(Additional!$AR$79,""proficiency with[a-z ]+""&lower(array_constrain(filter('Attack Info'!$B$7:$B180,'Attack Info'!$B$7:$B180<>"""",isnumber(find(lower('Attack Info'!$B$7:$B180),lower($AQ34)))),1,1))&""[a-z, ]+"&"\+[0-9]+ bonus to damage[a-z ]+with such weapons""),""[0-9]+?""),0)) +int(iferror(regexextract(regexextract(Additional!$AR$79,""\+[0-9] bonus to damage[a-z ]+""&lower(array_constrain(filter('Attack Info'!$B$7:$B180,'Attack Info'!$B$7:$B180<>"""",isnumber("&"find(lower('Attack Info'!$B$7:$B180),lower($AQ34)))),1,1))),""[0-9]+?""),0)) +if(and(isnumber(find(""melee"",lower($AU34))),iserror(find(""unarmed"",lower($AT34))),iserror(find(""natural"",lower($AT34))),iserror(find(""two-handed"",lower($R34&$BA34)))),du"&"eling,0) +if(isnumber(find(""thrown"",lower($BA34))),thrown,0) &""[""&$AS34&""]"","""") &if(and(PaladinLevel>=11,isnumber(find(""melee"",lower($AU34))),isnumber(find(lower($AT34),""simplemartial""))),""+1d8[radiant]"","""") &if($AX34<>""-"",""+""&$AX34&"""&"[""&$AY34&""]"","""") &if(and(isnumber(find(""pact"",lower($AQ34))),isnumber(find(""lifedrinker"",lower(invocations)))),""+""&chaMod&""[necrotic]"","""") &""|***""&textjoin("" "",True,if(and($AT34<>""-"",$AT34<>""Spell""),$AT34,""""),if($AU34<>""-"",$AU34"&",""""),if($AT34=""Spell"",$AT34,if(and($AT34<>""Unarmed"",$AT34<>""Natural""),""Weapon"","""")))&"" Attack.***"" &if($BA34<>""-"","" ""&$BA34,"""") &if(and(isnumber(find(""melee"",lower($AU34))),iserror(find(""unarmed"",lower($AT34))),iserror(find(""natur"&"al"",lower($AT34))),iserror(find(""two-handed"",lower($R34&$AV34)))),"" ""&duelingText,"""") &if(and(or(lower($AT34)=""unarmed"",lower($AT34)=""natural""),unarmedFighting),"" ""&unarmedText,"""") &if(and(""melee""=lower($AU34),lower($AT34)<>""unarmed"",is"&"number(find(""two-handed"",lower($R34&$BA34)))),"" ""&gwfText,"""") &if(and(isnumber(find(""offhand"",lower($R34))),twoWeaponFighting),"" ""&twfText,"""") &if(and(lower($AU34)=""ranged"",lower($AT34)<>""spell""),if(archeryText<>"""","" ""&archeryText,"""""&")&if(closeQuartersText<>"""","" ""&closeQuartersText,""""),"""") &if(isnumber(find(""thrown"",lower($BA34))),"" ""&thrownText,""""),"" -""),""+0"","""")")," -") -> - | AQ34: =IFERROR(__xludf.DUMMYFUNCTION("iferror(array_constrain(split(textjoin(""~"",True,filter('Attack Info'!$B$7:$AN180,'Attack Info'!$B$7:$B180<>"""",lower('Attack Info'!$B$7:$B180)=lower(R34))),""~""),1,12),"""")"),"") | BC34: {=if(and(strMod<>"-",dexMod<>"-"),if($AQ34<>"",if($AW34<>"-",$AW34,0) +if(isnumber(find(lower($AZ34),"strdexconintwischa")),if(indirect(lower($AZ34)&"Mod")<>"-",indirect(lower($AZ34)&"Mod"),0), if(or(isnumber(find("finesse",lower($BA34))),and($AV34<>"〇",MonkLevel<>"",MonkLevel>0)),max(strMod,dexMod),if(lower($AU34)="ranged",dexMod,strMod))),""),"-")} -> -
